<?xml version="1.0" encoding="UTF-8"?>
<testsuite errors="0" failures="2" file="subnet_calculator_tests.py" name="subnet_calculator_tests.TestValidateIpv6Address-20201004230819" skipped="0" tests="18" time="0.024" timestamp="2020-10-04T23:08:21">
	<testcase classname="subnet_calculator_tests.TestValidateIpv6Address" name="test_abbreviated_zero_at_eight_groups" time="0.003" timestamp="2020-10-04T23:08:20"/>
	<testcase classname="subnet_calculator_tests.TestValidateIpv6Address" name="test_abbreviated_zero_at_end_group" time="0.001" timestamp="2020-10-04T23:08:21"/>
	<testcase classname="subnet_calculator_tests.TestValidateIpv6Address" name="test_abbreviated_zero_at_middle_group" time="0.001" timestamp="2020-10-04T23:08:21"/>
	<testcase classname="subnet_calculator_tests.TestValidateIpv6Address" name="test_abbreviated_zero_one_above_eight_groups" time="0.001" timestamp="2020-10-04T23:08:21"/>
	<testcase classname="subnet_calculator_tests.TestValidateIpv6Address" name="test_abbreviated_zero_well_above_eight_groups" time="0.001" timestamp="2020-10-04T23:08:21"/>
	<testcase classname="subnet_calculator_tests.TestValidateIpv6Address" name="test_ipv6_with_a_middle_group_negative" time="0.001" timestamp="2020-10-04T23:08:21"/>
	<testcase classname="subnet_calculator_tests.TestValidateIpv6Address" name="test_ipv6_with_first_group_negative" time="0.001" timestamp="2020-10-04T23:08:21"/>
	<testcase classname="subnet_calculator_tests.TestValidateIpv6Address" name="test_ipv6_with_groups_at_eight" time="0.001" timestamp="2020-10-04T23:08:21"/>
	<testcase classname="subnet_calculator_tests.TestValidateIpv6Address" name="test_ipv6_with_groups_one_above_eight" time="0.001" timestamp="2020-10-04T23:08:21"/>
	<testcase classname="subnet_calculator_tests.TestValidateIpv6Address" name="test_ipv6_with_groups_well_above_eight" time="0.001" timestamp="2020-10-04T23:08:21"/>
	<testcase classname="subnet_calculator_tests.TestValidateIpv6Address" name="test_ipv6_with_last_group_negative" time="0.001" timestamp="2020-10-04T23:08:21"/>
	<testcase classname="subnet_calculator_tests.TestValidateIpv6Address" name="test_ipv6_with_letters_between_a_to_f_lowercase" time="0.001" timestamp="2020-10-04T23:08:21"/>
	<testcase classname="subnet_calculator_tests.TestValidateIpv6Address" name="test_ipv6_with_letters_between_a_to_f_uppercase" time="0.001" timestamp="2020-10-04T23:08:21"/>
	<testcase classname="subnet_calculator_tests.TestValidateIpv6Address" name="test_ipv6_with_letters_between_g_to_z_lowercase" time="0.001" timestamp="2020-10-04T23:08:21"/>
	<testcase classname="subnet_calculator_tests.TestValidateIpv6Address" name="test_ipv6_with_letters_between_g_to_z_uppercase" time="0.001" timestamp="2020-10-04T23:08:21"/>
	<testcase classname="subnet_calculator_tests.TestValidateIpv6Address" name="test_ipv6_with_no_groups" time="0.001" timestamp="2020-10-04T23:08:21"/>
	<testcase classname="subnet_calculator_tests.TestValidateIpv6Address" name="test_ipv6_with_groups_one_below_eight" time="0.003" timestamp="2020-10-04T23:08:21">
		<failure message="True is not false" type="AssertionError">
<![CDATA[Traceback (most recent call last):
  File "/usr/lib/python3.6/unittest/case.py", line 59, in testPartExecutor
    yield
  File "/usr/lib/python3.6/unittest/case.py", line 605, in run
    testMethod()
  File "/home/student/Documents/cs3280project2/src/unittest/python/subnet_calculator_tests.py", line 389, in test_ipv6_with_groups_one_below_eight
    self.assertFalse(is_valid)
  File "/usr/lib/python3.6/unittest/case.py", line 676, in assertFalse
    raise self.failureException(msg)
AssertionError: True is not false
]]>		</failure>
	</testcase>
	<testcase classname="subnet_calculator_tests.TestValidateIpv6Address" name="test_ipv6_with_groups_well_below_eight" time="0.002" timestamp="2020-10-04T23:08:21">
		<failure message="True is not false" type="AssertionError">
<![CDATA[Traceback (most recent call last):
  File "/usr/lib/python3.6/unittest/case.py", line 59, in testPartExecutor
    yield
  File "/usr/lib/python3.6/unittest/case.py", line 605, in run
    testMethod()
  File "/home/student/Documents/cs3280project2/src/unittest/python/subnet_calculator_tests.py", line 384, in test_ipv6_with_groups_well_below_eight
    self.assertFalse(is_valid)
  File "/usr/lib/python3.6/unittest/case.py", line 676, in assertFalse
    raise self.failureException(msg)
AssertionError: True is not false
]]>		</failure>
	</testcase>
</testsuite>
