<?xml version="1.0" encoding="UTF-8"?>
<testsuite errors="14" failures="0" file="subnet_calculator_tests.py" name="subnet_calculator_tests.TestCalculateIpv4Subnet-20201009130544" skipped="0" tests="27" time="0.047" timestamp="2020-10-09T13:05:44">
	<testcase classname="subnet_calculator_tests.TestCalculateIpv4Subnet" name="test_calculate_subnet_in_bit_format_maximum_ip_and_well_below_maximum_subnet" time="0.002" timestamp="2020-10-09T13:05:44"/>
	<testcase classname="subnet_calculator_tests.TestCalculateIpv4Subnet" name="test_calculate_subnet_in_bit_format_with_maximum_ip_and_maximum_subnet" time="0.001" timestamp="2020-10-09T13:05:44"/>
	<testcase classname="subnet_calculator_tests.TestCalculateIpv4Subnet" name="test_calculate_subnet_in_bit_format_with_maximum_ip_and_one_below_maximum_subnet" time="0.001" timestamp="2020-10-09T13:05:44"/>
	<testcase classname="subnet_calculator_tests.TestCalculateIpv4Subnet" name="test_calculate_subnet_in_bit_format_with_minimum_ip_and_one_above_minimum_subnet" time="0.001" timestamp="2020-10-09T13:05:44"/>
	<testcase classname="subnet_calculator_tests.TestCalculateIpv4Subnet" name="test_calculate_subnet_in_bit_format_with_minimum_ip_and_well_above_minimum_subnet" time="0.001" timestamp="2020-10-09T13:05:44"/>
	<testcase classname="subnet_calculator_tests.TestCalculateIpv4Subnet" name="test_calculate_subnet_in_bit_format_with_one_above_minimum_ip_and_minimum_subnet" time="0.001" timestamp="2020-10-09T13:05:44"/>
	<testcase classname="subnet_calculator_tests.TestCalculateIpv4Subnet" name="test_calculate_subnet_in_bit_format_with_one_above_minimum_ip_and_one_above_minimum_subnet" time="0.001" timestamp="2020-10-09T13:05:44"/>
	<testcase classname="subnet_calculator_tests.TestCalculateIpv4Subnet" name="test_calculate_subnet_in_bit_format_with_one_below_maximum_ip_and_maximum_subnet" time="0.001" timestamp="2020-10-09T13:05:44"/>
	<testcase classname="subnet_calculator_tests.TestCalculateIpv4Subnet" name="test_calculate_subnet_in_bit_format_with_one_below_maximum_ip_and_one_below_maximum_subnet" time="0.001" timestamp="2020-10-09T13:05:44"/>
	<testcase classname="subnet_calculator_tests.TestCalculateIpv4Subnet" name="test_calculate_subnet_in_bit_format_with_well_above_minimum_ip_and_minimum_subnet" time="0.001" timestamp="2020-10-09T13:05:44"/>
	<testcase classname="subnet_calculator_tests.TestCalculateIpv4Subnet" name="test_calculate_subnet_in_bit_format_with_well_above_minimum_ip_and_well_above_minimum_subnet" time="0.001" timestamp="2020-10-09T13:05:44"/>
	<testcase classname="subnet_calculator_tests.TestCalculateIpv4Subnet" name="test_calculate_subnet_in_bit_format_with_well_below_maximum_ip_and_maximum_subnet" time="0.001" timestamp="2020-10-09T13:05:44"/>
	<testcase classname="subnet_calculator_tests.TestCalculateIpv4Subnet" name="test_calculate_subnet_in_ip_format_with_well_below_maximum_ip_and_well_below_maximum_subnet" time="0.001" timestamp="2020-10-09T13:05:44"/>
	<testcase classname="subnet_calculator_tests.TestCalculateIpv4Subnet" name="test_calculate_subnet_in_bit_format_with_minimum_ip_and_minimum_subnet" time="0.004" timestamp="2020-10-09T13:05:44">
		<error message="invalid literal for int() with base 2: ''" type="ValueError">
<![CDATA[Traceback (most recent call last):
  File "/usr/lib/python3.6/unittest/case.py", line 59, in testPartExecutor
    yield
  File "/usr/lib/python3.6/unittest/case.py", line 605, in run
    testMethod()
  File "/home/student/Documents/cs3280project2/src/unittest/python/subnet_calculator_tests.py", line 760, in test_calculate_subnet_in_bit_format_with_minimum_ip_and_minimum_subnet
    subnet = subnet_calculator.calculate_ipv4_subnet('0.0.0.0', '')
  File "/home/student/Documents/cs3280project2/src/main/python/subnet_calculator.py", line 116, in calculate_ipv4_subnet
    current_netmask_as_integer = int(split_netmask[current_octet_index], 2)
ValueError: invalid literal for int() with base 2: ''
]]>		</error>
	</testcase>
	<testcase classname="subnet_calculator_tests.TestCalculateIpv4Subnet" name="test_calculate_subnet_in_ip_format_maximum_ip_and_well_below_maximum_subnet" time="0.002" timestamp="2020-10-09T13:05:44">
		<error message="invalid literal for int() with base 2: '255'" type="ValueError">
<![CDATA[Traceback (most recent call last):
  File "/usr/lib/python3.6/unittest/case.py", line 59, in testPartExecutor
    yield
  File "/usr/lib/python3.6/unittest/case.py", line 605, in run
    testMethod()
  File "/home/student/Documents/cs3280project2/src/unittest/python/subnet_calculator_tests.py", line 735, in test_calculate_subnet_in_ip_format_maximum_ip_and_well_below_maximum_subnet
    subnet = subnet_calculator.calculate_ipv4_subnet('255.255.255.255', '255.255.240.0')
  File "/home/student/Documents/cs3280project2/src/main/python/subnet_calculator.py", line 116, in calculate_ipv4_subnet
    current_netmask_as_integer = int(split_netmask[current_octet_index], 2)
ValueError: invalid literal for int() with base 2: '255'
]]>		</error>
	</testcase>
	<testcase classname="subnet_calculator_tests.TestCalculateIpv4Subnet" name="test_calculate_subnet_in_ip_format_with_maximum_ip_and_maximum_subnet" time="0.002" timestamp="2020-10-09T13:05:44">
		<error message="invalid literal for int() with base 2: '255'" type="ValueError">
<![CDATA[Traceback (most recent call last):
  File "/usr/lib/python3.6/unittest/case.py", line 59, in testPartExecutor
    yield
  File "/usr/lib/python3.6/unittest/case.py", line 605, in run
    testMethod()
  File "/home/student/Documents/cs3280project2/src/unittest/python/subnet_calculator_tests.py", line 725, in test_calculate_subnet_in_ip_format_with_maximum_ip_and_maximum_subnet
    subnet = subnet_calculator.calculate_ipv4_subnet('255.255.255.255', '255.255.255.254')
  File "/home/student/Documents/cs3280project2/src/main/python/subnet_calculator.py", line 116, in calculate_ipv4_subnet
    current_netmask_as_integer = int(split_netmask[current_octet_index], 2)
ValueError: invalid literal for int() with base 2: '255'
]]>		</error>
	</testcase>
	<testcase classname="subnet_calculator_tests.TestCalculateIpv4Subnet" name="test_calculate_subnet_in_ip_format_with_maximum_ip_and_one_below_maximum_subnet" time="0.002" timestamp="2020-10-09T13:05:44">
		<error message="invalid literal for int() with base 2: '255'" type="ValueError">
<![CDATA[Traceback (most recent call last):
  File "/usr/lib/python3.6/unittest/case.py", line 59, in testPartExecutor
    yield
  File "/usr/lib/python3.6/unittest/case.py", line 605, in run
    testMethod()
  File "/home/student/Documents/cs3280project2/src/unittest/python/subnet_calculator_tests.py", line 730, in test_calculate_subnet_in_ip_format_with_maximum_ip_and_one_below_maximum_subnet
    subnet = subnet_calculator.calculate_ipv4_subnet('255.255.255.255', '255.255.255.252')
  File "/home/student/Documents/cs3280project2/src/main/python/subnet_calculator.py", line 116, in calculate_ipv4_subnet
    current_netmask_as_integer = int(split_netmask[current_octet_index], 2)
ValueError: invalid literal for int() with base 2: '255'
]]>		</error>
	</testcase>
	<testcase classname="subnet_calculator_tests.TestCalculateIpv4Subnet" name="test_calculate_subnet_in_ip_format_with_minimum_ip_and_minimum_subnet" time="0.002" timestamp="2020-10-09T13:05:44">
		<error message="invalid literal for int() with base 2: '128'" type="ValueError">
<![CDATA[Traceback (most recent call last):
  File "/usr/lib/python3.6/unittest/case.py", line 59, in testPartExecutor
    yield
  File "/usr/lib/python3.6/unittest/case.py", line 605, in run
    testMethod()
  File "/home/student/Documents/cs3280project2/src/unittest/python/subnet_calculator_tests.py", line 690, in test_calculate_subnet_in_ip_format_with_minimum_ip_and_minimum_subnet
    subnet = subnet_calculator.calculate_ipv4_subnet('0.0.0.0', '128.0.0.0')
  File "/home/student/Documents/cs3280project2/src/main/python/subnet_calculator.py", line 116, in calculate_ipv4_subnet
    current_netmask_as_integer = int(split_netmask[current_octet_index], 2)
ValueError: invalid literal for int() with base 2: '128'
]]>		</error>
	</testcase>
	<testcase classname="subnet_calculator_tests.TestCalculateIpv4Subnet" name="test_calculate_subnet_in_ip_format_with_minimum_ip_and_one_above_minimum_subnet" time="0.002" timestamp="2020-10-09T13:05:44">
		<error message="invalid literal for int() with base 2: '192'" type="ValueError">
<![CDATA[Traceback (most recent call last):
  File "/usr/lib/python3.6/unittest/case.py", line 59, in testPartExecutor
    yield
  File "/usr/lib/python3.6/unittest/case.py", line 605, in run
    testMethod()
  File "/home/student/Documents/cs3280project2/src/unittest/python/subnet_calculator_tests.py", line 695, in test_calculate_subnet_in_ip_format_with_minimum_ip_and_one_above_minimum_subnet
    subnet = subnet_calculator.calculate_ipv4_subnet('0.0.0.0', '192.0.0.0')
  File "/home/student/Documents/cs3280project2/src/main/python/subnet_calculator.py", line 116, in calculate_ipv4_subnet
    current_netmask_as_integer = int(split_netmask[current_octet_index], 2)
ValueError: invalid literal for int() with base 2: '192'
]]>		</error>
	</testcase>
	<testcase classname="subnet_calculator_tests.TestCalculateIpv4Subnet" name="test_calculate_subnet_in_ip_format_with_minimum_ip_and_well_above_minimum_subnet" time="0.002" timestamp="2020-10-09T13:05:44">
		<error message="invalid literal for int() with base 2: '255'" type="ValueError">
<![CDATA[Traceback (most recent call last):
  File "/usr/lib/python3.6/unittest/case.py", line 59, in testPartExecutor
    yield
  File "/usr/lib/python3.6/unittest/case.py", line 605, in run
    testMethod()
  File "/home/student/Documents/cs3280project2/src/unittest/python/subnet_calculator_tests.py", line 700, in test_calculate_subnet_in_ip_format_with_minimum_ip_and_well_above_minimum_subnet
    subnet = subnet_calculator.calculate_ipv4_subnet('0.0.0.0', '255.240.0.0')
  File "/home/student/Documents/cs3280project2/src/main/python/subnet_calculator.py", line 116, in calculate_ipv4_subnet
    current_netmask_as_integer = int(split_netmask[current_octet_index], 2)
ValueError: invalid literal for int() with base 2: '255'
]]>		</error>
	</testcase>
	<testcase classname="subnet_calculator_tests.TestCalculateIpv4Subnet" name="test_calculate_subnet_in_ip_format_with_one_above_minimum_ip_and_minimum_subnet" time="0.002" timestamp="2020-10-09T13:05:44">
		<error message="invalid literal for int() with base 2: '128'" type="ValueError">
<![CDATA[Traceback (most recent call last):
  File "/usr/lib/python3.6/unittest/case.py", line 59, in testPartExecutor
    yield
  File "/usr/lib/python3.6/unittest/case.py", line 605, in run
    testMethod()
  File "/home/student/Documents/cs3280project2/src/unittest/python/subnet_calculator_tests.py", line 705, in test_calculate_subnet_in_ip_format_with_one_above_minimum_ip_and_minimum_subnet
    subnet = subnet_calculator.calculate_ipv4_subnet('1.1.1.1', '128.0.0.0')
  File "/home/student/Documents/cs3280project2/src/main/python/subnet_calculator.py", line 116, in calculate_ipv4_subnet
    current_netmask_as_integer = int(split_netmask[current_octet_index], 2)
ValueError: invalid literal for int() with base 2: '128'
]]>		</error>
	</testcase>
	<testcase classname="subnet_calculator_tests.TestCalculateIpv4Subnet" name="test_calculate_subnet_in_ip_format_with_one_above_minimum_ip_and_one_above_minimum_subnet" time="0.002" timestamp="2020-10-09T13:05:44">
		<error message="invalid literal for int() with base 2: '128'" type="ValueError">
<![CDATA[Traceback (most recent call last):
  File "/usr/lib/python3.6/unittest/case.py", line 59, in testPartExecutor
    yield
  File "/usr/lib/python3.6/unittest/case.py", line 605, in run
    testMethod()
  File "/home/student/Documents/cs3280project2/src/unittest/python/subnet_calculator_tests.py", line 715, in test_calculate_subnet_in_ip_format_with_one_above_minimum_ip_and_one_above_minimum_subnet
    subnet = subnet_calculator.calculate_ipv4_subnet('1.1.1.1', '128.0.0.0')
  File "/home/student/Documents/cs3280project2/src/main/python/subnet_calculator.py", line 116, in calculate_ipv4_subnet
    current_netmask_as_integer = int(split_netmask[current_octet_index], 2)
ValueError: invalid literal for int() with base 2: '128'
]]>		</error>
	</testcase>
	<testcase classname="subnet_calculator_tests.TestCalculateIpv4Subnet" name="test_calculate_subnet_in_ip_format_with_one_below_maximum_ip_and_maximum_subnet" time="0.002" timestamp="2020-10-09T13:05:44">
		<error message="invalid literal for int() with base 2: '255'" type="ValueError">
<![CDATA[Traceback (most recent call last):
  File "/usr/lib/python3.6/unittest/case.py", line 59, in testPartExecutor
    yield
  File "/usr/lib/python3.6/unittest/case.py", line 605, in run
    testMethod()
  File "/home/student/Documents/cs3280project2/src/unittest/python/subnet_calculator_tests.py", line 740, in test_calculate_subnet_in_ip_format_with_one_below_maximum_ip_and_maximum_subnet
    subnet = subnet_calculator.calculate_ipv4_subnet('254.254.254.254', '255.255.255.254')
  File "/home/student/Documents/cs3280project2/src/main/python/subnet_calculator.py", line 116, in calculate_ipv4_subnet
    current_netmask_as_integer = int(split_netmask[current_octet_index], 2)
ValueError: invalid literal for int() with base 2: '255'
]]>		</error>
	</testcase>
	<testcase classname="subnet_calculator_tests.TestCalculateIpv4Subnet" name="test_calculate_subnet_in_ip_format_with_one_below_maximum_ip_and_one_below_maximum_subnet" time="0.002" timestamp="2020-10-09T13:05:44">
		<error message="invalid literal for int() with base 2: '255'" type="ValueError">
<![CDATA[Traceback (most recent call last):
  File "/usr/lib/python3.6/unittest/case.py", line 59, in testPartExecutor
    yield
  File "/usr/lib/python3.6/unittest/case.py", line 605, in run
    testMethod()
  File "/home/student/Documents/cs3280project2/src/unittest/python/subnet_calculator_tests.py", line 750, in test_calculate_subnet_in_ip_format_with_one_below_maximum_ip_and_one_below_maximum_subnet
    subnet = subnet_calculator.calculate_ipv4_subnet('254.254.254.254', '255.255.255.252')
  File "/home/student/Documents/cs3280project2/src/main/python/subnet_calculator.py", line 116, in calculate_ipv4_subnet
    current_netmask_as_integer = int(split_netmask[current_octet_index], 2)
ValueError: invalid literal for int() with base 2: '255'
]]>		</error>
	</testcase>
	<testcase classname="subnet_calculator_tests.TestCalculateIpv4Subnet" name="test_calculate_subnet_in_ip_format_with_well_above_minimum_ip_and_minimum_subnet" time="0.002" timestamp="2020-10-09T13:05:44">
		<error message="invalid literal for int() with base 2: '128'" type="ValueError">
<![CDATA[Traceback (most recent call last):
  File "/usr/lib/python3.6/unittest/case.py", line 59, in testPartExecutor
    yield
  File "/usr/lib/python3.6/unittest/case.py", line 605, in run
    testMethod()
  File "/home/student/Documents/cs3280project2/src/unittest/python/subnet_calculator_tests.py", line 710, in test_calculate_subnet_in_ip_format_with_well_above_minimum_ip_and_minimum_subnet
    subnet = subnet_calculator.calculate_ipv4_subnet('160.160.160.160', '128.0.0.0')
  File "/home/student/Documents/cs3280project2/src/main/python/subnet_calculator.py", line 116, in calculate_ipv4_subnet
    current_netmask_as_integer = int(split_netmask[current_octet_index], 2)
ValueError: invalid literal for int() with base 2: '128'
]]>		</error>
	</testcase>
	<testcase classname="subnet_calculator_tests.TestCalculateIpv4Subnet" name="test_calculate_subnet_in_ip_format_with_well_above_minimum_ip_and_well_above_minimum_subnet" time="0.002" timestamp="2020-10-09T13:05:44">
		<error message="invalid literal for int() with base 2: '255'" type="ValueError">
<![CDATA[Traceback (most recent call last):
  File "/usr/lib/python3.6/unittest/case.py", line 59, in testPartExecutor
    yield
  File "/usr/lib/python3.6/unittest/case.py", line 605, in run
    testMethod()
  File "/home/student/Documents/cs3280project2/src/unittest/python/subnet_calculator_tests.py", line 720, in test_calculate_subnet_in_ip_format_with_well_above_minimum_ip_and_well_above_minimum_subnet
    subnet = subnet_calculator.calculate_ipv4_subnet('160.160.160.160', '255.248.0.0')
  File "/home/student/Documents/cs3280project2/src/main/python/subnet_calculator.py", line 116, in calculate_ipv4_subnet
    current_netmask_as_integer = int(split_netmask[current_octet_index], 2)
ValueError: invalid literal for int() with base 2: '255'
]]>		</error>
	</testcase>
	<testcase classname="subnet_calculator_tests.TestCalculateIpv4Subnet" name="test_calculate_subnet_in_ip_format_with_well_below_maximum_ip_and_maximum_subnet" time="0.002" timestamp="2020-10-09T13:05:44">
		<error message="invalid literal for int() with base 2: '255'" type="ValueError">
<![CDATA[Traceback (most recent call last):
  File "/usr/lib/python3.6/unittest/case.py", line 59, in testPartExecutor
    yield
  File "/usr/lib/python3.6/unittest/case.py", line 605, in run
    testMethod()
  File "/home/student/Documents/cs3280project2/src/unittest/python/subnet_calculator_tests.py", line 745, in test_calculate_subnet_in_ip_format_with_well_below_maximum_ip_and_maximum_subnet
    subnet = subnet_calculator.calculate_ipv4_subnet('160.160.160.160', '255.255.255.254')
  File "/home/student/Documents/cs3280project2/src/main/python/subnet_calculator.py", line 116, in calculate_ipv4_subnet
    current_netmask_as_integer = int(split_netmask[current_octet_index], 2)
ValueError: invalid literal for int() with base 2: '255'
]]>		</error>
	</testcase>
</testsuite>
