<?xml version="1.0" encoding="UTF-8"?>
<testsuite errors="0" failures="2" file="subnet_calculator_tests.py" name="subnet_calculator_tests.TestCalculateIpv4Subnet-20201007235020" skipped="0" tests="7" time="0.012" timestamp="2020-10-07T23:50:21">
	<testcase classname="subnet_calculator_tests.TestCalculateIpv4Subnet" name="test_calculate_ipv4_with_minimum_ip_and_minimum_subnet" time="0.001" timestamp="2020-10-07T23:50:21"/>
	<testcase classname="subnet_calculator_tests.TestCalculateIpv4Subnet" name="test_calculate_ipv4_with_minimum_ip_and_one_above_minimum_subnet" time="0.001" timestamp="2020-10-07T23:50:21"/>
	<testcase classname="subnet_calculator_tests.TestCalculateIpv4Subnet" name="test_calculate_ipv4_with_minimum_ip_and_well_above_minimum_subnet" time="0.001" timestamp="2020-10-07T23:50:21"/>
	<testcase classname="subnet_calculator_tests.TestCalculateIpv4Subnet" name="test_calculate_ipv4_with_one_above_minimum_ip_and_minimum_subnet" time="0.001" timestamp="2020-10-07T23:50:21"/>
	<testcase classname="subnet_calculator_tests.TestCalculateIpv4Subnet" name="test_calculate_ipv4_with_well_above_minimum_ip_and_minimum_subnet" time="0.001" timestamp="2020-10-07T23:50:21"/>
	<testcase classname="subnet_calculator_tests.TestCalculateIpv4Subnet" name="test_calculate_ipv4_with_one_above_minimum_ip_and_one_above_minimum_subnet" time="0.004" timestamp="2020-10-07T23:50:21">
		<failure message="'1.1.1.1' != '0.0.0.0'
- 1.1.1.1
+ 0.0.0.0
" type="AssertionError">
<![CDATA[Traceback (most recent call last):
  File "/usr/lib/python3.6/unittest/case.py", line 59, in testPartExecutor
    yield
  File "/usr/lib/python3.6/unittest/case.py", line 605, in run
    testMethod()
  File "/home/student/Documents/cs3280project2/src/unittest/python/subnet_calculator_tests.py", line 650, in test_calculate_ipv4_with_one_above_minimum_ip_and_one_above_minimum_subnet
    self.assertEquals('1.1.1.1', subnet)
  File "/usr/lib/python3.6/unittest/case.py", line 1321, in deprecated_func
    return original_func(*args, **kwargs)
  File "/usr/lib/python3.6/unittest/case.py", line 829, in assertEqual
    assertion_func(first, second, msg=msg)
  File "/usr/lib/python3.6/unittest/case.py", line 1203, in assertMultiLineEqual
    self.fail(self._formatMessage(msg, standardMsg))
  File "/usr/lib/python3.6/unittest/case.py", line 670, in fail
    raise self.failureException(msg)
AssertionError: '1.1.1.1' != '0.0.0.0'
- 1.1.1.1
+ 0.0.0.0

]]>		</failure>
	</testcase>
	<testcase classname="subnet_calculator_tests.TestCalculateIpv4Subnet" name="test_calculate_ipv4_with_well_above_minimum_ip_and_well_above_minimum_subnet" time="0.003" timestamp="2020-10-07T23:50:21">
		<failure message="'1.1.1.1' != '160.160.0.0'
- 1.1.1.1
+ 160.160.0.0
" type="AssertionError">
<![CDATA[Traceback (most recent call last):
  File "/usr/lib/python3.6/unittest/case.py", line 59, in testPartExecutor
    yield
  File "/usr/lib/python3.6/unittest/case.py", line 605, in run
    testMethod()
  File "/home/student/Documents/cs3280project2/src/unittest/python/subnet_calculator_tests.py", line 655, in test_calculate_ipv4_with_well_above_minimum_ip_and_well_above_minimum_subnet
    self.assertEquals('1.1.1.1', subnet)
  File "/usr/lib/python3.6/unittest/case.py", line 1321, in deprecated_func
    return original_func(*args, **kwargs)
  File "/usr/lib/python3.6/unittest/case.py", line 829, in assertEqual
    assertion_func(first, second, msg=msg)
  File "/usr/lib/python3.6/unittest/case.py", line 1203, in assertMultiLineEqual
    self.fail(self._formatMessage(msg, standardMsg))
  File "/usr/lib/python3.6/unittest/case.py", line 670, in fail
    raise self.failureException(msg)
AssertionError: '1.1.1.1' != '160.160.0.0'
- 1.1.1.1
+ 160.160.0.0

]]>		</failure>
	</testcase>
</testsuite>
