<?xml version="1.0" encoding="UTF-8"?>
<testsuite errors="0" failures="1" file="subnet_calculator_tests.py" name="subnet_calculator_tests.TestValidateSubnetMaskIpFormat-20201006103547" skipped="0" tests="1" time="0.004" timestamp="2020-10-06T10:35:48">
	<testcase classname="subnet_calculator_tests.TestValidateSubnetMaskIpFormat" name="test_empty_subnet" time="0.004" timestamp="2020-10-06T10:35:48">
		<failure message="True is not false" type="AssertionError">
<![CDATA[Traceback (most recent call last):
  File "/usr/lib/python3.6/unittest/case.py", line 59, in testPartExecutor
    yield
  File "/usr/lib/python3.6/unittest/case.py", line 605, in run
    testMethod()
  File "/home/student/Documents/cs3280project2/src/unittest/python/subnet_calculator_tests.py", line 426, in test_empty_subnet
    self.assertFalse(is_valid)
  File "/usr/lib/python3.6/unittest/case.py", line 676, in assertFalse
    raise self.failureException(msg)
AssertionError: True is not false
]]>		</failure>
	</testcase>
</testsuite>
